Workbook

Sheet Assumptions
A1: POSEIDON.AI — Financial Model Assumptions
A2: B2C SaaS | 36-Month Projection | Realistic Growth Scenario
A4: PRICING & MONETIZATION
A5: Tier | B5: Monthly Price | C5: Annual Price | D5: Engines Included
A6: Free | B6: 0 | C6: 0 | D6: Dashboard + Basic Protect (3 alerts/mo)
A7: Plus | B7: 7.99 | C7: =B7*12*(1-B28) -> 76.704 | D7: Full Protect + Grow (forecasting, savings insights)
A8: Pro | B8: 19.99 | C8: =B8*12*(1-B28) -> 191.904 | D8: All 4 Engines: Protect + Grow + Execute + Govern
A10: USER GROWTH
A11: Launch users (Month 1) | B11: 10000 | C11: Beta waitlist + ProductHunt launch
A12: Initial organic signup rate | B12: 0.1 | C12: Starting MoM rate; decays by factor below
A13: Paid acquisition (users/mo, M1) | B13: 500 | C13: Starting paid spend; scales with budget
A14: Paid acquisition growth rate | B14: 0.05 | C14: MoM increase in paid spend
A15: Viral coefficient (K-factor) | B15: 0.08 | C15: Invites per user that convert
A16: K-factor decay (monthly) | B16: 0.98 | C16: Monthly multiplier on K; 0.98 = halves over ~35 months
A17: Organic growth decay factor | B17: 0.955 | C17: Rate multiplier per month; 0.955 = ~3.5% rate by M36
A18: CONVERSION & CHURN
A19: Free → Plus conversion rate | B19: 0.035 | C19: Monthly; industry 3-7% for freemium fintech
A20: Free → Pro conversion rate | B20: 0.008 | C20: Monthly; direct-to-Pro skip
A21: Plus → Pro upgrade rate | B21: 0.02 | C21: Monthly upgrade from Plus to Pro
A22: Free churn rate (monthly) | B22: 0.08 | C22: Free users who stop using
A23: Plus churn rate (monthly) | B23: 0.05 | C23: Paid churn; B2C SaaS median ~5-7%, set at lower end
A24: Pro churn rate (monthly) | B24: 0.03 | C24: Lower churn at higher engagement tier; B2C floor ~3%
A26: PRICING ASSUMPTIONS
A27: Annual plan adoption rate | B27: 0.35 | C27: Pct of paid users choosing annual
A28: Annual discount | B28: 0.2 | C28: 20% off vs monthly
A29: Blended ARPU — Plus | B29: =B7*(1-B27) + (B7*(1-B28))*B27 -> 7.4307 | C29: Weighted monthly + annual mix
A30: Blended ARPU — Pro | B30: =B8*(1-B27) + (B8*(1-B28))*B27 -> 18.5907
A32: COST STRUCTURE
A33: COGS per paid user / mo | B33: 2 | C33: Cloud infra + AI inference + data feeds (per-user marginal cost incl. AI API calls); AI-first premium
A34: COGS per free user / mo | B34: 0.15 | C34: Minimal compute for free tier (dashboard rendering, basic alerts)
A35: CAC — Organic | B35: 3.5 | C35: Content + SEO + referral program cost per signup
A36: CAC — Paid | B36: 28 | C36: Blended CPI across Meta, Google, TikTok; fintech B2C $30-50 range, set at lower end
A37: CAC — Blended (formula) | B37: =(B35*0.7 + B36*0.3) -> 10.85 | C37: ~70% organic / 30% paid mix
A39: HEADCOUNT PLAN
A40: Role | B40: M1-6 | C40: M7-18 | D40: M19-36
A41: Engineering | B41: 4 | C41: 6 | D41: 7
A42: Product & Design | B42: 1 | C42: 1 | D42: 2
A43: Data Science / ML | B43: 2 | C43: 2 | D43: 3
A44: Marketing & Growth | B44: 1 | C44: 1 | D44: 3
A45: Sales & Partnerships | B45: 0 | C45: 0 | D45: 1
...

Sheet User Growth
A1: POSEIDON.AI — User Growth Model
A2: 36-Month Projection by Tier
A4: Metric | B4: Units | C4: M1 | D4: M2 | E4: M3 | F4: M4 | G4: M5 | H4: M6 | I4: M7 | J4: M8 | K4: M9 | L4: M10 | M4: M11 | N4: M12 | O4: M13 | P4: M14 | Q4: M15 | R4: M16 | S4: M17 | T4: M18 | U4: M19 | V4: M20 | W4: M21 | X4: M22 | Y4: M23 | Z4: M24 | AA4: M25 | AB4: M26 | AC4: M27 | AD4: M28 | AE4: M29 | AF4: M30 | AG4: M31 | AH4: M32 | AI4: M33 | AJ4: M34 | AK4: M35 | AL4: M36
A5: NEW USER ACQUISITION
A6: New organic signups | B6: # | C6: =Assumptions!B11 -> 10000 | D6: =ROUND(C6*(1+Assumptions!$B$12*Assumptions!$B$17^(COLUMN()-3)),0) -> 10955 | E6: =ROUND(D6*(1+Assumptions!$B$12*Assumptions!$B$17^(COLUMN()-3)),0) -> 11954 | F6: =ROUND(E6*(1+Assumptions!$B$12*Assumptions!$B$17^(COLUMN()-3)),0) -> 12995 | G6: =ROUND(F6*(1+Assumptions!$B$12*Assumptions!$B$17^(COLUMN()-3)),0) -> 14076 | H6: =ROUND(G6*(1+Assumptions!$B$12*Assumptions!$B$17^(COLUMN()-3)),0) -> 15194 | I6: =ROUND(H6*(1+Assumptions!$B$12*Assumptions!$B$17^(COLUMN()-3)),0) -> 16347 | J6: =ROUND(I6*(1+Assumptions!$B$12*Assumptions!$B$17^(COLUMN()-3)),0) -> 17531 | K6: =ROUND(J6*(1+Assumptions!$B$12*Assumptions!$B$17^(COLUMN()-3)),0) -> 18744 | ... AL6: =ROUND(AK6*(1+Assumptions!$B$12*Assumptions!$B$17^(COLUMN()-3)),0) -> 52119
A7: New paid acquisition | B7: # | C7: =Assumptions!B13 -> 500 | D7: =ROUND(C7*(1+Assumptions!$B$14*Assumptions!$B$17^(COLUMN()-3)),0) -> 524 | E7: =ROUND(D7*(1+Assumptions!$B$14*Assumptions!$B$17^(COLUMN()-3)),0) -> 548 | F7: =ROUND(E7*(1+Assumptions!$B$14*Assumptions!$B$17^(COLUMN()-3)),0) -> 572 | G7: =ROUND(F7*(1+Assumptions!$B$14*Assumptions!$B$17^(COLUMN()-3)),0) -> 596 | H7: =ROUND(G7*(1+Assumptions!$B$14*Assumptions!$B$17^(COLUMN()-3)),0) -> 620 | I7: =ROUND(H7*(1+Assumptions!$B$14*Assumptions!$B$17^(COLUMN()-3)),0) -> 644 | J7: =ROUND(I7*(1+Assumptions!$B$14*Assumptions!$B$17^(COLUMN()-3)),0) -> 667 | K7: =ROUND(J7*(1+Assumptions!$B$14*Assumptions!$B$17^(COLUMN()-3)),0) -> 690 | ... AL7: =ROUND(AK7*(1+Assumptions!$B$14*Assumptions!$B$17^(COLUMN()-3)),0) -> 1155
A8: Viral / referral signups | B8: # | C8: =0 -> 0 | D8: =ROUND((C15+C21+C26)*Assumptions!$B$15*Assumptions!$B$16^(COLUMN()-4),0) -> 771 | E8: =ROUND((D15+D21+D26)*Assumptions!$B$15*Assumptions!$B$16^(COLUMN()-4),0) -> 1577 | F8: =ROUND((E15+E21+E26)*Assumptions!$B$15*Assumptions!$B$16^(COLUMN()-4),0) -> 2415 | G8: =ROUND((F15+F21+F26)*Assumptions!$B$15*Assumptions!$B$16^(COLUMN()-4),0) -> 3284 | H8: =ROUND((G15+G21+G26)*Assumptions!$B$15*Assumptions!$B$16^(COLUMN()-4),0) -> 4182 | I8: =ROUND((H15+H21+H26)*Assumptions!$B$15*Assumptions!$B$16^(COLUMN()-4),0) -> 5107 | J8: =ROUND((I15+I21+I26)*Assumptions!$B$15*Assumptions!$B$16^(COLUMN()-4),0) -> 6055 | K8: =ROUND((J15+J21+J26)*Assumptions!$B$15*Assumptions!$B$16^(COLUMN()-4),0) -> 7024 | ... AL8: =ROUND((AK15+AK21+AK26)*Assumptions!$B$15*Assumptions!$B$16^(COLUMN()-4),0) -> 29712
A9: Total new signups | B9: # | C9: =C6+C7+C8 -> 10500 | D9: =D6+D7+D8 -> 12250 | E9: =E6+E7+E8 -> 14079 | F9: =F6+F7+F8 -> 15982 | G9: =G6+G7+G8 -> 17956 | H9: =H6+H7+H8 -> 19996 | I9: =I6+I7+I8 -> 22098 | J9: =J6+J7+J8 -> 24253 | ... AL9: =AL6+AL7+AL8 -> 82986
A10: FREE TIER USERS
A11: Free — Beginning of Month | B11: # | C11: =C9 -> 10500 | D11: =C15+D9 -> 21458 | E11: =D15+E9 -> 32897 | F11: =E15+F9 -> 44833 | G11: =F15+G9 -> 57274 | H11: =G15+H9 -> 70225 | I11: =H15+I9 -> 83685 | J11: =I15+J9 -> 97645 | K11: =J15+K9 -> 112092 | ... AL11: =AK15+AL9 -> 568328
A12: Less: Convert to Plus | B12: # | C12: =ROUND(C11*Assumptions!$B$19,0) -> 368 | D12: =ROUND(D11*Assumptions!$B$19,0) -> 751 | E12: =ROUND(E11*Assumptions!$B$19,0) -> 1151 | F12: =ROUND(F11*Assumptions!$B$19,0) -> 1569 | G12: =ROUND(G11*Assumptions!$B$19,0) -> 2005 | H12: =ROUND(H11*Assumptions!$B$19,0) -> 2458 | I12: =ROUND(I11*Assumptions!$B$19,0) -> 2929 | J12: =ROUND(J11*Assumptions!$B$19,0) -> 3418 | ... AL12: =ROUND(AL11*Assumptions!$B$19,0) -> 19891
A13: Less: Convert to Pro | B13: # | C13: =ROUND(C11*Assumptions!$B$20,0) -> 84 | D13: =ROUND(D11*Assumptions!$B$20,0) -> 172 | E13: =ROUND(E11*Assumptions!$B$20,0) -> 263 | F13: =ROUND(F11*Assumptions!$B$20,0) -> 359 | G13: =ROUND(G11*Assumptions!$B$20,0) -> 458 | H13: =ROUND(H11*Assumptions!$B$20,0) -> 562 | I13: =ROUND(I11*Assumptions!$B$20,0) -> 669 | J13: =ROUND(J11*Assumptions!$B$20,0) -> 781 | ... AL13: =ROUND(AL11*Assumptions!$B$20,0) -> 4547
A14: Less: Churn | B14: # | C14: =ROUND(C11*Assumptions!$B$22,0) -> 840 | D14: =ROUND(D11*Assumptions!$B$22,0) -> 1717 | E14: =ROUND(E11*Assumptions!$B$22,0) -> 2632 | F14: =ROUND(F11*Assumptions!$B$22,0) -> 3587 | G14: =ROUND(G11*Assumptions!$B$22,0) -> 4582 | H14: =ROUND(H11*Assumptions!$B$22,0) -> 5618 | I14: =ROUND(I11*Assumptions!$B$22,0) -> 6695 | J14: =ROUND(J11*Assumptions!$B$22,0) -> 7812 | ... AL14: =ROUND(AL11*Assumptions!$B$22,0) -> 45466
A15: Free — End of Month | B15: # | C15: =C11-C12-C13-C14 -> 9208 | D15: =D11-D12-D13-D14 -> 18818 | E15: =E11-E12-E13-E14 -> 28851 | F15: =F11-F12-F13-F14 -> 39318 | G15: =G11-G12-G13-G14 -> 50229 | H15: =H11-H12-H13-H14 -> 61587 | I15: =I11-I12-I13-I14 -> 73392 | J15: =J11-J12-J13-J14 -> 85634 | ... AL15: =AL11-AL12-AL13-AL14 -> 498424
A16: PLUS TIER USERS ($7.99/mo)
A17: Plus — Beginning of Month | B17: # | C17: =0 -> 0 | D17: =C21 -> 343 | E17: =D21 -> 1017 | F17: =E21 -> 2017 | G17: =F21 -> 3335 | H17: =G21 -> 4966 | I17: =H21 -> 6905 | J17: =I21 -> 9145 | K17: =J21 -> 11684 | ... AL17: =AK21 -> 163023
A18: Add: Conversions from Free | B18: # | C18: =C12 -> 368 | D18: =D12 -> 751 | E18: =E12 -> 1151 | F18: =F12 -> 1569 | G18: =G12 -> 2005 | H18: =H12 -> 2458 | I18: =I12 -> 2929 | J18: =J12 -> 3418 | ... AL18: =AL12 -> 19891
A19: Less: Upgrade to Pro | B19: # | C19: =ROUND((C17+C18)*Assumptions!$B$21,0) -> 7 | D19: =ROUND((D17+D18)*Assumptions!$B$21,0) -> 22 | E19: =ROUND((E17+E18)*Assumptions!$B$21,0) -> 43 | F19: =ROUND((F17+F18)*Assumptions!$B$21,0) -> 72 | G19: =ROUND((G17+G18)*Assumptions!$B$21,0) -> 107 | H19: =ROUND((H17+H18)*Assumptions!$B$21,0) -> 148 | I19: =ROUND((I17+I18)*Assumptions!$B$21,0) -> 197 | J19: =ROUND((J17+J18)*Assumptions!$B$21,0) -> 251 | ... AL19: =ROUND((AL17+AL18)*Assumptions!$B$21,0) -> 3658
A20: Less: Churn | B20: # | C20: =ROUND((C17+C18)*Assumptions!$B$23,0) -> 18 | D20: =ROUND((D17+D18)*Assumptions!$B$23,0) -> 55 | E20: =ROUND((E17+E18)*Assumptions!$B$23,0) -> 108 | F20: =ROUND((F17+F18)*Assumptions!$B$23,0) -> 179 | G20: =ROUND((G17+G18)*Assumptions!$B$23,0) -> 267 | H20: =ROUND((H17+H18)*Assumptions!$B$23,0) -> 371 | I20: =ROUND((I17+I18)*Assumptions!$B$23,0) -> 492 | J20: =ROUND((J17+J18)*Assumptions!$B$23,0) -> 628 | ... AL20: =ROUND((AL17+AL18)*Assumptions!$B$23,0) -> 9146
A21: Plus — End of Month | B21: # | C21: =C17+C18-C19-C20 -> 343 | D21: =D17+D18-D19-D20 -> 1017 | E21: =E17+E18-E19-E20 -> 2017 | F21: =F17+F18-F19-F20 -> 3335 | G21: =G17+G18-G19-G20 -> 4966 | H21: =H17+H18-H19-H20 -> 6905 | I21: =I17+I18-I19-I20 -> 9145 | J21: =J17+J18-J19-J20 -> 11684 | ... AL21: =AL17+AL18-AL19-AL20 -> 170110
A22: PRO TIER USERS ($19.99/mo)
A23: Pro — Beginning of Month | B23: # | C23: =0 -> 0 | D23: =C26 -> 88 | E23: =D26 -> 274 | F23: =E26 -> 563 | G23: =F26 -> 964 | H23: =G26 -> 1483 | I23: =H26 -> 2127 | J23: =I26 -> 2903 | K23: =J26 -> 3817 | ... AL23: =AK26 -> 89800
A24: Add: Conversions (Free + Plus) | B24: # | C24: =C13+C19 -> 91 | D24: =D13+D19 -> 194 | E24: =E13+E19 -> 306 | F24: =F13+F19 -> 431 | G24: =G13+G19 -> 565 | H24: =H13+H19 -> 710 | I24: =I13+I19 -> 866 | J24: =J13+J19 -> 1032 | ... AL24: =AL13+AL19 -> 8205
A25: Less: Churn | B25: # | C25: =ROUND((C23+C24)*Assumptions!$B$24,0) -> 3 | D25: =ROUND((D23+D24)*Assumptions!$B$24,0) -> 8 | E25: =ROUND((E23+E24)*Assumptions!$B$24,0) -> 17 | F25: =ROUND((F23+F24)*Assumptions!$B$24,0) -> 30 | G25: =ROUND((G23+G24)*Assumptions!$B$24,0) -> 46 | H25: =ROUND((H23+H24)*Assumptions!$B$24,0) -> 66 | I25: =ROUND((I23+I24)*Assumptions!$B$24,0) -> 90 | J25: =ROUND((J23+J24)*Assumptions!$B$24,0) -> 118 | ... AL25: =ROUND((AL23+AL24)*Assumptions!$B$24,0) -> 2940
A26: Pro — End of Month | B26: # | C26: =C23+C24-C25 -> 88 | D26: =D23+D24-D25 -> 274 | E26: =E23+E24-E25 -> 563 | F26: =F23+F24-F25 -> 964 | G26: =G23+G24-G25 -> 1483 | H26: =H23+H24-H25 -> 2127 | I26: =I23+I24-I25 -> 2903 | J26: =J23+J24-J25 -> 3817 | ... AL26: =AL23+AL24-AL25 -> 95065
A27: TOTAL METRICS
A28: Total MAU | B28: # | C28: =C15+C21+C26 -> 9639 | D28: =D15+D21+D26 -> 20109 | E28: =E15+E21+E26 -> 31431 | F28: =F15+F21+F26 -> 43617 | G28: =G15+G21+G26 -> 56678 | H28: =H15+H21+H26 -> 70619 | I28: =I15+I21+I26 -> 85440 | J28: =J15+J21+J26 -> 101135 | ... AL28: =AL15+AL21+AL26 -> 763599
A29: Total Paid Users | B29: # | C29: =C21+C26 -> 431 | D29: =D21+D26 -> 1291 | E29: =E21+E26 -> 2580 | F29: =F21+F26 -> 4299 | G29: =G21+G26 -> 6449 | H29: =H21+H26 -> 9032 | I29: =I21+I26 -> 12048 | J29: =J21+J26 -> 15501 | ... AL29: =AL21+AL26 -> 265175
A30: Paid % | B30: % | C30: =IF(C28=0,0,C29/C28) -> 0.044714182 | D30: =IF(D28=0,0,D29/D28) -> 0.064200109 | E30: =IF(E28=0,0,E29/E28) -> 0.082084566 | F30: =IF(F28=0,0,F29/F28) -> 0.098562487 | G30: =IF(G28=0,0,G29/G28) -> 0.11378313 | H30: =IF(H28=0,0,H29/H28) -> 0.12789759 | I30: =IF(I28=0,0,I29/I28) -> 0.14101124 | J30: =IF(J28=0,0,J29/J28) -> 0.15327038 | ... AL30: =IF(AL28=0,0,AL29/AL28) -> 0.34726997

Sheet Revenue
A1: POSEIDON.AI — Revenue Model
A2: MRR / ARR by Tier
A4: Metric | B4: Units | C4: M1 | D4: M2 | E4: M3 | F4: M4 | G4: M5 | H4: M6 | I4: M7 | J4: M8 | K4: M9 | L4: M10 | M4: M11 | N4: M12 | O4: M13 | P4: M14 | Q4: M15 | R4: M16 | S4: M17 | T4: M18 | U4: M19 | V4: M20 | W4: M21 | X4: M22 | Y4: M23 | Z4: M24 | AA4: M25 | AB4: M26 | AC4: M27 | AD4: M28 | AE4: M29 | AF4: M30 | AG4: M31 | AH4: M32 | AI4: M33 | AJ4: M34 | AK4: M35 | AL4: M36
A5: MRR BY TIER
A6: Plus MRR | B6: $ | C6: ='User Growth'!C21*Assumptions!$B$29 -> 2548.7301 | D6: ='User Growth'!D21*Assumptions!$B$29 -> 7557.0219 | E6: ='User Growth'!E21*Assumptions!$B$29 -> 14987.722 | F6: ='User Growth'!F21*Assumptions!$B$29 -> 24781.385 | G6: ='User Growth'!G21*Assumptions!$B$29 -> 36900.856 | H6: ='User Growth'!H21*Assumptions!$B$29 -> 51308.984 | I6: ='User Growth'!I21*Assumptions!$B$29 -> 67953.751 | J6: ='User Growth'!J21*Assumptions!$B$29 -> 86820.299 | ... AL6: ='User Growth'!AL21*Assumptions!$B$29 -> 1264036.4
A7: Pro MRR | B7: $ | C7: ='User Growth'!C26*Assumptions!$B$30 -> 1635.9816 | D7: ='User Growth'!D26*Assumptions!$B$30 -> 5093.8518 | E7: ='User Growth'!E26*Assumptions!$B$30 -> 10466.564 | F7: ='User Growth'!F26*Assumptions!$B$30 -> 17921.435 | G7: ='User Growth'!G26*Assumptions!$B$30 -> 27570.008 | H7: ='User Growth'!H26*Assumptions!$B$30 -> 39542.419 | I7: ='User Growth'!I26*Assumptions!$B$30 -> 53968.802 | J7: ='User Growth'!J26*Assumptions!$B$30 -> 70960.702 | ... AL7: ='User Growth'!AL26*Assumptions!$B$30 -> 1767324.9
A8: Total MRR | B8: $ | C8: =C6+C7 -> 4184.7117 | D8: =D6+D7 -> 12650.874 | E8: =E6+E7 -> 25454.286 | F8: =F6+F7 -> 42702.819 | G8: =G6+G7 -> 64470.864 | H8: =H6+H7 -> 90851.402 | I8: =I6+I7 -> 121922.55 | J8: =J6+J7 -> 157781 | ... AL8: =AL6+AL7 -> 3031361.3
A9: ARR (MRR x 12) | B9: $ | C9: =C8*12 -> 50216.54 | D9: =D8*12 -> 151810.48 | E9: =E8*12 -> 305451.43 | F9: =F8*12 -> 512433.83 | G9: =G8*12 -> 773650.37 | H9: =H8*12 -> 1090216.8 | I9: =I8*12 -> 1463070.6 | J9: =J8*12 -> 1893372 | ... AL9: =AL8*12 -> 36376335
A10: MRR MOVEMENTS
A11: New MRR (new conversions) | B11: $ | C11: ='User Growth'!C12*Assumptions!$B$29 + 'User Growth'!C13*Assumptions!$B$30 -> 4296.1164 | D11: ='User Growth'!D12*Assumptions!$B$29 + 'User Growth'!D13*Assumptions!$B$30 -> 8778.0561 | E11: ='User Growth'!E12*Assumptions!$B$29 + 'User Growth'!E13*Assumptions!$B$30 -> 13442.09 | F11: ='User Growth'!F12*Assumptions!$B$29 + 'User Growth'!F13*Assumptions!$B$30 -> 18332.83 | G11: ='User Growth'!G12*Assumptions!$B$29 + 'User Growth'!G13*Assumptions!$B$30 -> 23413.094 | H11: ='User Growth'!H12*Assumptions!$B$29 + 'User Growth'!H13*Assumptions!$B$30 -> 28712.634 | I11: ='User Growth'!I12*Assumptions!$B$29 + 'User Growth'!I13*Assumptions!$B$30 -> 34201.699 | J11: ='User Growth'!J12*Assumptions!$B$29 + 'User Growth'!J13*Assumptions!$B$30 -> 39917.469 | ... AL11: ='User Growth'!AL12*Assumptions!$B$29 + 'User Growth'!AL13*Assumptions!$B$30 -> 232335.97
A12: Expansion MRR (upgrades) | B12: $ | C12: ='User Growth'!C19*(Assumptions!$B$30-Assumptions!$B$29) -> 78.12 | D12: ='User Growth'!D19*(Assumptions!$B$30-Assumptions!$B$29) -> 245.52 | E12: ='User Growth'!E19*(Assumptions!$B$30-Assumptions!$B$29) -> 479.88 | F12: ='User Growth'!F19*(Assumptions!$B$30-Assumptions!$B$29) -> 803.52 | G12: ='User Growth'!G19*(Assumptions!$B$30-Assumptions!$B$29) -> 1194.12 | H12: ='User Growth'!H19*(Assumptions!$B$30-Assumptions!$B$29) -> 1651.68 | I12: ='User Growth'!I19*(Assumptions!$B$30-Assumptions!$B$29) -> 2198.52 | J12: ='User Growth'!J19*(Assumptions!$B$30-Assumptions!$B$29) -> 2801.16 | ... AL12: ='User Growth'!AL19*(Assumptions!$B$30-Assumptions!$B$29) -> 40823.28
A13: Churned MRR | B13: $ | C13: ='User Growth'!C20*Assumptions!$B$29 + 'User Growth'!C25*Assumptions!$B$30 -> 189.5247 | D13: ='User Growth'!D20*Assumptions!$B$29 + 'User Growth'!D25*Assumptions!$B$30 -> 557.4141 | E13: ='User Growth'!E20*Assumptions!$B$29 + 'User Growth'!E25*Assumptions!$B$30 -> 1118.5575 | F13: ='User Growth'!F20*Assumptions!$B$29 + 'User Growth'!F25*Assumptions!$B$30 -> 1887.8163 | G13: ='User Growth'!G20*Assumptions!$B$29 + 'User Growth'!G25*Assumptions!$B$30 -> 2839.1691 | H13: ='User Growth'!H20*Assumptions!$B$29 + 'User Growth'!H25*Assumptions!$B$30 -> 3983.7759 | I13: ='User Growth'!I20*Assumptions!$B$29 + 'User Growth'!I25*Assumptions!$B$30 -> 5329.0674 | J13: ='User Growth'!J20*Assumptions!$B$29 + 'User Growth'!J25*Assumptions!$B$30 -> 6860.1822 | ... AL13: ='User Growth'!AL20*Assumptions!$B$29 + 'User Growth'!AL25*Assumptions!$B$30 -> 122617.84
A14: Net New MRR | B14: $ | C14: =C11+C12-C13 -> 4184.7117 | D14: =D11+D12-D13 -> 8466.162 | E14: =E11+E12-E13 -> 12803.412 | F14: =F11+F12-F13 -> 17248.533 | G14: =G11+G12-G13 -> 21768.045 | H14: =H11+H12-H13 -> 26380.538 | I14: =I11+I12-I13 -> 31071.151 | J14: =J11+J12-J13 -> 35858.447 | ... AL14: =AL11+AL12-AL13 -> 150541.41
A15: REVENUE
A16: Monthly Revenue | B16: $ | C16: =C8 -> 4184.7117 | D16: =D8 -> 12650.874 | E16: =E8 -> 25454.286 | F16: =F8 -> 42702.819 | G16: =G8 -> 64470.864 | H16: =H8 -> 90851.402 | I16: =I8 -> 121922.55 | J16: =J8 -> 157781 | ... AL16: =AL8 -> 3031361.3
A17: Cumulative Revenue | B17: $ | C17: =C16 -> 4184.7117 | D17: =C17+D16 -> 16835.585 | E17: =D17+E16 -> 42289.871 | F17: =E17+F16 -> 84992.691 | G17: =F17+G16 -> 149463.55 | H17: =G17+H16 -> 240314.96 | I17: =H17+I16 -> 362237.51 | J17: =I17+J16 -> 520018.51 | K17: =J17+K16 -> 718504.78 | ... AL17: =AK17+AL16 -> 38930138
A18: Blended ARPU (paid users) | B18: $ | C18: =IF('User Growth'!C29=0,0,C8/'User Growth'!C29) -> 9.7093079 | D18: =IF('User Growth'!D29=0,0,D8/'User Growth'!D29) -> 9.7992825 | E18: =IF('User Growth'!E29=0,0,E8/'User Growth'!E29) -> 9.8660023 | F18: =IF('User Growth'!F29=0,0,F8/'User Growth'!F29) -> 9.9331983 | G18: =IF('User Growth'!G29=0,0,G8/'User Growth'!G29) -> 9.9970328 | H18: =IF('User Growth'!H29=0,0,H8/'User Growth'!H29) -> 10.058836 | I18: =IF('User Growth'!I29=0,0,I8/'User Growth'!I29) -> 10.119734 | J18: =IF('User Growth'!J29=0,0,J8/'User Growth'!J29) -> 10.178763 | ... AL18: =IF('User Growth'!AL29=0,0,AL8/'User Growth'!AL29) -> 11.43155
A19: Net Revenue Retention (NRR) | B19: % | C19: 0 | D19: =IF(C8=0,0,(C8+D12-D13)/C8) -> 0.9254682 | E19: =IF(D8=0,0,(D8+E12-E13)/D8) -> 0.94951515 | F19: =IF(E8=0,0,(E8+F12-F13)/E8) -> 0.95740221 | G19: =IF(F8=0,0,(F8+G12-G13)/F8) -> 0.9614768 | H19: =IF(G8=0,0,(G8+H12-H13)/G8) -> 0.96382713 | I19: =IF(H8=0,0,(H8+I12-I13)/H8) -> 0.96554211 | J19: =IF(I8=0,0,(I8+J12-J13)/I8) -> 0.96670819 | K19: =IF(J8=0,0,(J8+K12-K13)/J8) -> 0.96754222 | ... AL19: =IF(AK8=0,0,(AK8+AL12-AL13)/AK8) -> 0.97160719

Sheet Costs
A1: POSEIDON.AI — Cost Structure
A2: COGS + OpEx + Headcount
A4: Metric | B4: Units | C4: M1 | D4: M2 | E4: M3 | F4: M4 | G4: M5 | H4: M6 | I4: M7 | J4: M8 | K4: M9 | L4: M10 | M4: M11 | N4: M12 | O4: M13 | P4: M14 | Q4: M15 | R4: M16 | S4: M17 | T4: M18 | U4: M19 | V4: M20 | W4: M21 | X4: M22 | Y4: M23 | Z4: M24 | AA4: M25 | AB4: M26 | AC4: M27 | AD4: M28 | AE4: M29 | AF4: M30 | AG4: M31 | AH4: M32 | AI4: M33 | AJ4: M34 | AK4: M35 | AL4: M36
A5: COST OF GOODS SOLD (COGS)
A6: COGS — Free users | B6: $ | C6: ='User Growth'!C15*Assumptions!$B$34 -> 1381.2 | D6: ='User Growth'!D15*Assumptions!$B$34 -> 2822.7 | E6: ='User Growth'!E15*Assumptions!$B$34 -> 4327.65 | F6: ='User Growth'!F15*Assumptions!$B$34 -> 5897.7 | G6: ='User Growth'!G15*Assumptions!$B$34 -> 7534.35 | H6: ='User Growth'!H15*Assumptions!$B$34 -> 9238.05 | I6: ='User Growth'!I15*Assumptions!$B$34 -> 11008.8 | J6: ='User Growth'!J15*Assumptions!$B$34 -> 12845.1 | ... AL6: ='User Growth'!AL15*Assumptions!$B$34 -> 74763.6
A7: COGS — Paid users | B7: $ | C7: ='User Growth'!C29*Assumptions!$B$33 -> 862 | D7: ='User Growth'!D29*Assumptions!$B$33 -> 2582 | E7: ='User Growth'!E29*Assumptions!$B$33 -> 5160 | F7: ='User Growth'!F29*Assumptions!$B$33 -> 8598 | G7: ='User Growth'!G29*Assumptions!$B$33 -> 12898 | H7: ='User Growth'!H29*Assumptions!$B$33 -> 18064 | I7: ='User Growth'!I29*Assumptions!$B$33 -> 24096 | J7: ='User Growth'!J29*Assumptions!$B$33 -> 31002 | ... AL7: ='User Growth'!AL29*Assumptions!$B$33 -> 530350
A8: Total COGS | B8: $ | C8: =C6+C7 -> 2243.2 | D8: =D6+D7 -> 5404.7 | E8: =E6+E7 -> 9487.65 | F8: =F6+F7 -> 14495.7 | G8: =G6+G7 -> 20432.35 | H8: =H6+H7 -> 27302.05 | I8: =I6+I7 -> 35104.8 | J8: =J6+J7 -> 43847.1 | ... AL8: =AL6+AL7 -> 605113.6
A9: HEADCOUNT COSTS
A10: Headcount (FTEs) | B10: # | C10: =Assumptions!B48 -> 9 | D10: =Assumptions!B48 -> 9 | E10: =Assumptions!B48 -> 9 | F10: =Assumptions!B48 -> 9 | G10: =Assumptions!B48 -> 9 | H10: =Assumptions!B48 -> 9 | I10: =Assumptions!C48 -> 12 | J10: =Assumptions!C48 -> 12 | K10: =Assumptions!C48 -> 12 | L10: =Assumptions!C48 -> 12 | M10: =Assumptions!C48 -> 12 | N10: =Assumptions!C48 -> 12 | O10: =Assumptions!C48 -> 12 | P10: =Assumptions!C48 -> 12 | Q10: =Assumptions!C48 -> 12 | R10: =Assumptions!C48 -> 12 | S10: =Assumptions!C48 -> 12 | T10: =Assumptions!C48 -> 12 | U10: =Assumptions!D48 -> 25 | V10: =Assumptions!D48 -> 25 | W10: =Assumptions!D48 -> 25 | X10: =Assumptions!D48 -> 25 | Y10: =Assumptions!D48 -> 25 | Z10: =Assumptions!D48 -> 25 | AA10: =Assumptions!D48 -> 25 | AB10: =Assumptions!D48 -> 25 | AC10: =Assumptions!D48 -> 25 | AD10: =Assumptions!D48 -> 25 | AE10: =Assumptions!D48 -> 25 | AF10: =Assumptions!D48 -> 25 | AG10: =Assumptions!D48 -> 25 | AH10: =Assumptions!D48 -> 25 | AI10: =Assumptions!D48 -> 25 | AJ10: =Assumptions!D48 -> 25 | AK10: =Assumptions!D48 -> 25 | AL10: =Assumptions!D48 -> 25
A11: Total Payroll | B11: $ | C11: =C10*Assumptions!$B$49/12 -> 112500 | D11: =D10*Assumptions!$B$49/12 -> 112500 | E11: =E10*Assumptions!$B$49/12 -> 112500 | F11: =F10*Assumptions!$B$49/12 -> 112500 | G11: =G10*Assumptions!$B$49/12 -> 112500 | H11: =H10*Assumptions!$B$49/12 -> 112500 | I11: =I10*Assumptions!$B$49/12 -> 150000 | J11: =J10*Assumptions!$B$49/12 -> 150000 | ... AL11: =AL10*Assumptions!$B$49/12 -> 312500
A12: OPERATING EXPENSES
A13: Cloud infrastructure (base + scaling) | B13: $ | C13: =Assumptions!$B$59+'User Growth'!C28*Assumptions!$B$66 -> 10192.78 | D13: =Assumptions!$B$59+'User Growth'!D28*Assumptions!$B$66 -> 10402.18 | E13: =Assumptions!$B$59+'User Growth'!E28*Assumptions!$B$66 -> 10628.62 | F13: =Assumptions!$B$59+'User Growth'!F28*Assumptions!$B$66 -> 10872.34 | G13: =Assumptions!$B$59+'User Growth'!G28*Assumptions!$B$66 -> 11133.56 | H13: =Assumptions!$B$59+'User Growth'!H28*Assumptions!$B$66 -> 11412.38 | I13: =Assumptions!$B$59+'User Growth'!I28*Assumptions!$B$66 -> 11708.8 | J13: =Assumptions!$B$59+'User Growth'!J28*Assumptions!$B$66 -> 12022.7 | ... AL13: =Assumptions!$B$59+'User Growth'!AL28*Assumptions!$B$66 -> 25271.98
A14: AI/ML model costs (base + scaling) | B14: $ | C14: =Assumptions!$B$60+'User Growth'!C28*Assumptions!$B$67 -> 5096.39 | D14: =Assumptions!$B$60+'User Growth'!D28*Assumptions!$B$67 -> 5201.09 | E14: =Assumptions!$B$60+'User Growth'!E28*Assumptions!$B$67 -> 5314.31 | F14: =Assumptions!$B$60+'User Growth'!F28*Assumptions!$B$67 -> 5436.17 | G14: =Assumptions!$B$60+'User Growth'!G28*Assumptions!$B$67 -> 5566.78 | H14: =Assumptions!$B$60+'User Growth'!H28*Assumptions!$B$67 -> 5706.19 | I14: =Assumptions!$B$60+'User Growth'!I28*Assumptions!$B$67 -> 5854.4 | J14: =Assumptions!$B$60+'User Growth'!J28*Assumptions!$B$67 -> 6011.35 | ... AL14: =Assumptions!$B$60+'User Growth'!AL28*Assumptions!$B$67 -> 12635.99
A15: Data feeds & APIs | B15: $ | C15: =Assumptions!$B$61 -> 4000 | D15: =Assumptions!$B$61 -> 4000 | E15: =Assumptions!$B$61 -> 4000 | F15: =Assumptions!$B$61 -> 4000 | G15: =Assumptions!$B$61 -> 4000 | H15: =Assumptions!$B$61 -> 4000 | I15: =Assumptions!$B$61 -> 4000 | J15: =Assumptions!$B$61 -> 4000 | ... AL15: =Assumptions!$B$61 -> 4000
A16: Marketing & Growth | B16: $ | C16: =MAX(5000, Revenue!C16*Assumptions!$B$62) -> 5000 | D16: =MAX(5000, Revenue!D16*Assumptions!$B$62) -> 5000 | E16: =MAX(5000, Revenue!E16*Assumptions!$B$62) -> 6363.5715 | F16: =MAX(5000, Revenue!F16*Assumptions!$B$62) -> 10675.705 | G16: =MAX(5000, Revenue!G16*Assumptions!$B$62) -> 16117.716 | H16: =MAX(5000, Revenue!H16*Assumptions!$B$62) -> 22712.851 | I16: =MAX(5000, Revenue!I16*Assumptions!$B$62) -> 30480.638 | J16: =MAX(5000, Revenue!J16*Assumptions!$B$62) -> 39445.25 | ... AL16: =MAX(5000, Revenue!AL16*Assumptions!$B$62) -> 757840.32
A17: Office & Misc | B17: $ | C17: =Assumptions!$B$63 -> 0 | D17: =Assumptions!$B$63 -> 0 | E17: =Assumptions!$B$63 -> 0 | F17: =Assumptions!$B$63 -> 0 | G17: =Assumptions!$B$63 -> 0 | H17: =Assumptions!$B$63 -> 0 | I17: =Assumptions!$B$63 -> 0 | J17: =Assumptions!$B$63 -> 0 | ... AL17: =Assumptions!$B$63 -> 0
A18: Total OpEx (non-COGS) | B18: $ | C18: =C11+C13+C14+C15+C16+C17 -> 136789.17 | D18: =D11+D13+D14+D15+D16+D17 -> 137103.27 | E18: =E11+E13+E14+E15+E16+E17 -> 138806.5 | F18: =F11+F13+F14+F15+F16+F17 -> 143484.21 | G18: =G11+G13+G14+G15+G16+G17 -> 149318.06 | H18: =H11+H13+H14+H15+H16+H17 -> 156331.42 | I18: =I11+I13+I14+I15+I16+I17 -> 202043.84 | J18: =J11+J13+J14+J15+J16+J17 -> 211479.3 | ... AL18: =AL11+AL13+AL14+AL15+AL16+AL17 -> 1112248.3
A19: PROFITABILITY
A20: Total Costs | B20: $ | C20: =C8+C18 -> 139032.37 | D20: =D8+D18 -> 142507.97 | E20: =E8+E18 -> 148294.15 | F20: =F8+F18 -> 157979.91 | G20: =G8+G18 -> 169750.41 | H20: =H8+H18 -> 183633.47 | I20: =I8+I18 -> 237148.64 | J20: =J8+J18 -> 255326.4 | ... AL20: =AL8+AL18 -> 1717361.9
A21: Gross Profit | B21: $ | C21: =Revenue!C16-C8 -> 1941.5117 | D21: =Revenue!D16-D8 -> 7246.1737 | E21: =Revenue!E16-E8 -> 15966.636 | F21: =Revenue!F16-F8 -> 28207.119 | G21: =Revenue!G16-G8 -> 44038.514 | H21: =Revenue!H16-H8 -> 63549.352 | I21: =Revenue!I16-I8 -> 86817.754 | J21: =Revenue!J16-J8 -> 113933.9 | ... AL21: =Revenue!AL16-AL8 -> 2426247.7
A22: Gross Margin | B22: % | C22: =IF(Revenue!C16=0,0,C21/Revenue!C16) -> 0.46395351 | D22: =IF(Revenue!D16=0,0,D21/Revenue!D16) -> 0.57278049 | E22: =IF(Revenue!E16=0,0,E21/Revenue!E16) -> 0.62726709 | F22: =IF(Revenue!F16=0,0,F21/Revenue!F16) -> 0.66054466 | G22: =IF(Revenue!G16=0,0,G21/Revenue!G16) -> 0.68307622 | H22: =IF(Revenue!H16=0,0,H21/Revenue!H16) -> 0.69948675 | I22: =IF(Revenue!I16=0,0,I21/Revenue!I16) -> 0.71207296 | J22: =IF(Revenue!J16=0,0,J21/Revenue!J16) -> 0.72210152 | ... AL22: =IF(Revenue!AL16=0,0,AL21/Revenue!AL16) -> 0.80038222
A23: Operating Profit (EBITDA proxy) | B23: $ | C23: =Revenue!C16-C20 -> -134847.66 | D23: =Revenue!D16-D20 -> -129857.1 | E23: =Revenue!E16-E20 -> -122839.87 | F23: =Revenue!F16-F20 -> -115277.1 | G23: =Revenue!G16-G20 -> -105279.54 | H23: =Revenue!H16-H20 -> -92782.068 | I23: =Revenue!I16-I20 -> -115226.08 | J23: =Revenue!J16-J20 -> -97545.399 | ... AL23: =Revenue!AL16-AL20 -> 1313999.4
A24: Operating Margin | B24: % | C24: =IF(Revenue!C16=0,0,C23/Revenue!C16) -> -32.223883 | D24: =IF(Revenue!D16=0,0,D23/Revenue!D16) -> -10.264674 | E24: =IF(Revenue!E16=0,0,E23/Revenue!E16) -> -4.825901 | F24: =IF(Revenue!F16=0,0,F23/Revenue!F16) -> -2.6995195 | G24: =IF(Revenue!G16=0,0,G23/Revenue!G16) -> -1.6329786 | H24: =IF(Revenue!H16=0,0,H23/Revenue!H16) -> -1.0212508 | I24: =IF(Revenue!I16=0,0,I23/Revenue!I16) -> -0.94507605 | J24: =IF(Revenue!J16=0,0,J23/Revenue!J16) -> -0.61823286 | ... AL24: =IF(Revenue!AL16=0,0,AL23/Revenue!AL16) -> 0.43346842

Sheet CAC Analysis
A1: POSEIDON.AI — Customer Acquisition Cost Analysis
A2: Dynamic CAC by Channel, Blended, and Cumulative
A4: Metric | B4: Units | C4: M1 | D4: M2 | E4: M3 | F4: M4 | G4: M5 | H4: M6 | I4: M7 | J4: M8 | K4: M9 | L4: M10 | M4: M11 | N4: M12 | O4: M13 | P4: M14 | Q4: M15 | R4: M16 | S4: M17 | T4: M18 | U4: M19 | V4: M20 | W4: M21 | X4: M22 | Y4: M23 | Z4: M24 | AA4: M25 | AB4: M26 | AC4: M27 | AD4: M28 | AE4: M29 | AF4: M30 | AG4: M31 | AH4: M32 | AI4: M33 | AJ4: M34 | AK4: M35 | AL4: M36
A5: ACQUISITION INPUTS
A6: New organic signups | B6: # | C6: ='User Growth'!C6 -> 10000 | D6: ='User Growth'!D6 -> 10955 | E6: ='User Growth'!E6 -> 11954 | F6: ='User Growth'!F6 -> 12995 | G6: ='User Growth'!G6 -> 14076 | H6: ='User Growth'!H6 -> 15194 | I6: ='User Growth'!I6 -> 16347 | J6: ='User Growth'!J6 -> 17531 | ... AL6: ='User Growth'!AL6 -> 52119
A7: New paid acquisition | B7: # | C7: ='User Growth'!C7 -> 500 | D7: ='User Growth'!D7 -> 524 | E7: ='User Growth'!E7 -> 548 | F7: ='User Growth'!F7 -> 572 | G7: ='User Growth'!G7 -> 596 | H7: ='User Growth'!H7 -> 620 | I7: ='User Growth'!I7 -> 644 | J7: ='User Growth'!J7 -> 667 | ... AL7: ='User Growth'!AL7 -> 1155
A8: Viral / referral signups | B8: # | C8: ='User Growth'!C8 -> 0 | D8: ='User Growth'!D8 -> 771 | E8: ='User Growth'!E8 -> 1577 | F8: ='User Growth'!F8 -> 2415 | G8: ='User Growth'!G8 -> 3284 | H8: ='User Growth'!H8 -> 4182 | I8: ='User Growth'!I8 -> 5107 | J8: ='User Growth'!J8 -> 6055 | ... AL8: ='User Growth'!AL8 -> 29712
A9: Total new signups | B9: # | C9: ='User Growth'!C9 -> 10500 | D9: ='User Growth'!D9 -> 12250 | E9: ='User Growth'!E9 -> 14079 | F9: ='User Growth'!F9 -> 15982 | G9: ='User Growth'!G9 -> 17956 | H9: ='User Growth'!H9 -> 19996 | I9: ='User Growth'!I9 -> 22098 | J9: ='User Growth'!J9 -> 24253 | ... AL9: ='User Growth'!AL9 -> 82986
A10: Marketing & Growth spend | B10: $ | C10: =Costs!C16 -> 5000 | D10: =Costs!D16 -> 5000 | E10: =Costs!E16 -> 6363.5715 | F10: =Costs!F16 -> 10675.705 | G10: =Costs!G16 -> 16117.716 | H10: =Costs!H16 -> 22712.851 | I10: =Costs!I16 -> 30480.638 | J10: =Costs!J16 -> 39445.25 | ... AL10: =Costs!AL16 -> 757840.32
A12: CAC BY CHANNEL
A13: CAC — Organic (assumption) | B13: $ | C13: =Assumptions!$B$35 -> 3.5 | D13: =Assumptions!$B$35 -> 3.5 | E13: =Assumptions!$B$35 -> 3.5 | F13: =Assumptions!$B$35 -> 3.5 | G13: =Assumptions!$B$35 -> 3.5 | H13: =Assumptions!$B$35 -> 3.5 | I13: =Assumptions!$B$35 -> 3.5 | J13: =Assumptions!$B$35 -> 3.5 | ... AL13: =Assumptions!$B$35 -> 3.5
A14: CAC — Paid (assumption) | B14: $ | C14: =Assumptions!$B$36 -> 28 | D14: =Assumptions!$B$36 -> 28 | E14: =Assumptions!$B$36 -> 28 | F14: =Assumptions!$B$36 -> 28 | G14: =Assumptions!$B$36 -> 28 | H14: =Assumptions!$B$36 -> 28 | I14: =Assumptions!$B$36 -> 28 | J14: =Assumptions!$B$36 -> 28 | ... AL14: =Assumptions!$B$36 -> 28
A15: Organic spend (implied) | B15: $ | C15: =C13*(C6+C8) -> 35000 | D15: =D13*(D6+D8) -> 41041 | E15: =E13*(E6+E8) -> 47358.5 | F15: =F13*(F6+F8) -> 53935 | G15: =G13*(G6+G8) -> 60760 | H15: =H13*(H6+H8) -> 67816 | I15: =I13*(I6+I8) -> 75089 | J15: =J13*(J6+J8) -> 82551 | ... AL15: =AL13*(AL6+AL8) -> 286408.5
A16: Paid spend (implied) | B16: $ | C16: =C14*C7 -> 14000 | D16: =D14*D7 -> 14672 | E16: =E14*E7 -> 15344 | F16: =F14*F7 -> 16016 | G16: =G14*G7 -> 16688 | H16: =H14*H7 -> 17360 | I16: =I14*I7 -> 18032 | J16: =J14*J7 -> 18676 | ... AL16: =AL14*AL7 -> 32340
A18: BLENDED CAC METRICS
A19: Blended CAC (assumption-based) | B19: $ | C19: =C13*(C6+C8)/C9+C14*C7/C9 -> 4.6666667 | D19: =D13*(D6+D8)/D9+D14*D7/D9 -> 4.548 | E19: =E13*(E6+E8)/E9+E14*E7/E9 -> 4.4536189 | F19: =F13*(F6+F8)/F9+F14*F7/F9 -> 4.3768615 | G19: =G13*(G6+G8)/G9+G14*G7/G9 -> 4.3132101 | H19: =H13*(H6+H8)/H9+H14*H7/H9 -> 4.2596519 | I19: =I13*(I6+I8)/I9+I14*I7/I9 -> 4.2140013 | J19: =J13*(J6+J8)/J9+J14*J7/J9 -> 4.1737929 | ... AL19: =AL13*(AL6+AL8)/AL9+AL14*AL7/AL9 -> 3.8409913
A20: Blended CAC (actual: spend ÷ signups) | B20: $ | C20: =C10/C9 -> 0.47619048 | D20: =D10/D9 -> 0.40816327 | E20: =E10/E9 -> 0.4519903 | F20: =F10/F9 -> 0.66798303 | G20: =G10/G9 -> 0.89762286 | H20: =H10/H9 -> 1.1358697 | I20: =I10/I9 -> 1.3793392 | J20: =J10/J9 -> 1.626407 | ... AL20: =AL10/AL9 -> 9.1321466
A21: Organic % of signups | B21: % | C21: =C6/C9 -> 0.95238095 | D21: =D6/D9 -> 0.89428571 | E21: =E6/E9 -> 0.84906598 | F21: =F6/F9 -> 0.81310224 | G21: =G6/G9 -> 0.78391624 | H21: =H6/H9 -> 0.75985197 | I21: =I6/I9 -> 0.7397502 | J21: =J6/J9 -> 0.72283841 | ... AL21: =AL6/AL9 -> 0.62804569
A22: Paid % of signups | B22: % | C22: =C7/C9 -> 0.047619048 | D22: =D7/D9 -> 0.04277551 | E22: =E7/E9 -> 0.038923219 | F22: =F7/F9 -> 0.035790264 | G22: =G7/G9 -> 0.033192248 | H22: =H7/H9 -> 0.031006201 | I22: =I7/I9 -> 0.029142909 | J22: =J7/J9 -> 0.027501752 | ... AL22: =AL7/AL9 -> 0.01391801
A23: Viral % of signups | B23: % | C23: =C8/C9 -> 0 | D23: =D8/D9 -> 0.062938776 | E23: =E8/E9 -> 0.1120108 | F23: =F8/F9 -> 0.1511075 | G23: =G8/G9 -> 0.18289151 | H23: =H8/H9 -> 0.20914183 | I23: =I8/I9 -> 0.23110689 | J23: =J8/J9 -> 0.24965984 | ... AL23: =AL8/AL9 -> 0.3580363
A25: CUMULATIVE CAC
A26: Cumulative marketing spend | B26: $ | C26: =C10 -> 5000 | D26: =C26+D10 -> 10000 | E26: =D26+E10 -> 16363.572 | F26: =E26+F10 -> 27039.276 | G26: =F26+G10 -> 43156.992 | H26: =G26+H10 -> 65869.843 | I26: =H26+I10 -> 96350.481 | J26: =I26+J10 -> 135795.73 | K26: =J26+K10 -> 185417.3 | ... AL26: =AK26+AL10 -> 9738325.6
A27: Cumulative new signups | B27: # | C27: =C9 -> 10500 | D27: =C27+D9 -> 22750 | E27: =D27+E9 -> 36829 | F27: =E27+F9 -> 52811 | G27: =F27+G9 -> 70767 | H27: =G27+H9 -> 90763 | I27: =H27+I9 -> 112861 | J27: =I27+J9 -> 137114 | K27: =J27+K9 -> 163572 | ... AL27: =AK27+AL9 -> 1722667
A28: Cumulative CAC (spend ÷ signups) | B28: $ | C28: =C26/C27 -> 0.47619048 | D28: =D26/D27 -> 0.43956044 | E28: =E26/E27 -> 0.44431213 | F28: =F26/F27 -> 0.51200084 | G28: =G26/G27 -> 0.60984629 | H28: =H26/H27 -> 0.72573453 | I28: =I26/I27 -> 0.85370927 | J28: =J26/J27 -> 0.9903856 | ... AL28: =AL26/AL27 -> 5.6530517
A30: CAC EFFICIENCY
A31: Total paid users | B31: # | C31: ='User Growth'!C29 -> 431 | D31: ='User Growth'!D29 -> 1291 | E31: ='User Growth'!E29 -> 2580 | F31: ='User Growth'!F29 -> 4299 | G31: ='User Growth'!G29 -> 6449 | H31: ='User Growth'!H29 -> 9032 | I31: ='User Growth'!I29 -> 12048 | J31: ='User Growth'!J29 -> 15501 | ... AL31: ='User Growth'!AL29 -> 265175
A32: Marketing spend per paid user | B32: $ | C32: =IF(C31>0,C10/C31,0) -> 11.600928 | D32: =IF(D31>0,D10/D31,0) -> 3.8729667 | E32: =IF(E31>0,E10/E31,0) -> 2.4665006 | F32: =IF(F31>0,F10/F31,0) -> 2.4832996 | G32: =IF(G31>0,G10/G31,0) -> 2.4992582 | H32: =IF(H31>0,H10/H31,0) -> 2.5147089 | I32: =IF(I31>0,I10/I31,0) -> 2.5299335 | J32: =IF(J31>0,J10/J31,0) -> 2.5446907 | ... AL32: =IF(AL31>0,AL10/AL31,0) -> 2.8578875
A33: LTV / CAC — Plus (actual CAC) | B33: x | C33: =IF(C20>0,(Assumptions!$B$29-Assumptions!$B$33)*(1/Assumptions!$B$23)/C20,0) -> 228.0894 | D33: =IF(D20>0,(Assumptions!$B$29-Assumptions!$B$33)*(1/Assumptions!$B$23)/D20,0) -> 266.1043 | E33: =IF(E20>0,(Assumptions!$B$29-Assumptions!$B$33)*(1/Assumptions!$B$23)/E20,0) -> 240.30161 | F33: =IF(F20>0,(Assumptions!$B$29-Assumptions!$B$33)*(1/Assumptions!$B$23)/F20,0) -> 162.59994 | G33: =IF(G20>0,(Assumptions!$B$29-Assumptions!$B$33)*(1/Assumptions!$B$23)/G20,0) -> 121.00182 | H33: =IF(H20>0,(Assumptions!$B$29-Assumptions!$B$33)*(1/Assumptions!$B$23)/H20,0) -> 95.621883 | I33: =IF(I20>0,(Assumptions!$B$29-Assumptions!$B$33)*(1/Assumptions!$B$23)/I20,0) -> 78.743501 | J33: =IF(J20>0,(Assumptions!$B$29-Assumptions!$B$33)*(1/Assumptions!$B$23)/J20,0) -> 66.78156 | ... AL33: =IF(AL20>0,(Assumptions!$B$29-Assumptions!$B$33)*(1/Assumptions!$B$23)/AL20,0) -> 11.893589
A34: LTV / CAC — Pro (actual CAC) | B34: x | C34: =IF(C20>0,(Assumptions!$B$30-Assumptions!$B$33)*(1/Assumptions!$B$24)/C20,0) -> 1161.349 | D34: =IF(D20>0,(Assumptions!$B$30-Assumptions!$B$33)*(1/Assumptions!$B$24)/D20,0) -> 1354.9072 | E34: =IF(E20>0,(Assumptions!$B$30-Assumptions!$B$33)*(1/Assumptions!$B$24)/E20,0) -> 1223.5292 | F34: =IF(F20>0,(Assumptions!$B$30-Assumptions!$B$33)*(1/Assumptions!$B$24)/F20,0) -> 827.90027 | G34: =IF(G20>0,(Assumptions!$B$30-Assumptions!$B$33)*(1/Assumptions!$B$24)/G20,0) -> 616.09765 | H34: =IF(H20>0,(Assumptions!$B$30-Assumptions!$B$33)*(1/Assumptions!$B$24)/H20,0) -> 486.87216 | I34: =IF(I20>0,(Assumptions!$B$30-Assumptions!$B$33)*(1/Assumptions!$B$24)/I20,0) -> 400.93352 | J34: =IF(J20>0,(Assumptions!$B$30-Assumptions!$B$33)*(1/Assumptions!$B$24)/J20,0) -> 340.02763 | ... AL34: =IF(AL20>0,(Assumptions!$B$30-Assumptions!$B$33)*(1/Assumptions!$B$24)/AL20,0) -> 60.557869

Sheet Unit Economics
A1: POSEIDON.AI — Unit Economics
A2: CAC, LTV, Payback Period, Contribution Margin
A4: CUSTOMER ACQUISITION COST (CAC)
A5: Blended CAC | B5: =Assumptions!B37 -> 10.85
A6: CAC Payback — Plus (months) | B6: =Assumptions!B37/(Assumptions!B29-Assumptions!B33) -> 1.9979008 | C6: Months to recover CAC from Plus subscriber
A7: CAC Payback — Pro (months) | B7: =Assumptions!B37/(Assumptions!B30-Assumptions!B33) -> 0.65398084
A9: LIFETIME VALUE (LTV)
A10: Plus avg lifetime (months) | B10: =1/Assumptions!B23 -> 20 | C10: 1 / monthly churn rate
A11: Pro avg lifetime (months) | B11: =1/Assumptions!B24 -> 33.333333
A12: LTV — Plus | B12: =(Assumptions!B29-Assumptions!B33)*B10 -> 108.614 | C12: (ARPU - COGS) x avg lifetime
A13: LTV — Pro | B13: =(Assumptions!B30-Assumptions!B33)*B11 -> 553.02333
A14: LTV / CAC — Plus | B14: =B12/Assumptions!B37 -> 10.010507 | C14: Target: >3.0x for healthy SaaS
A15: LTV / CAC — Pro | B15: =B13/Assumptions!B37 -> 50.969892
A17: CONTRIBUTION MARGIN (PER USER / MONTH)
A18: Plus: Revenue per user | B18: =Assumptions!B29 -> 7.4307
A19: Plus: COGS per user | B19: =Assumptions!B33 -> 2
A20: Plus: Contribution margin | B20: =B18-B19 -> 5.4307
A21: Plus: Contribution margin % | B21: =B20/B18 -> 0.73084635
A23: Pro: Revenue per user | B23: =Assumptions!B30 -> 18.5907
A24: Pro: COGS per user | B24: =Assumptions!B33 -> 2
A25: Pro: Contribution margin | B25: =B23-B24 -> 16.5907
A26: Pro: Contribution margin % | B26: =B25/B23 -> 0.89241933
A28: SNAPSHOT METRICS (from model) | B28: M12 | C28: M24 | D28: M36
A29: Total MAU | B29: ='User Growth'!N28 -> 172386 | C29: ='User Growth'!Z28 -> 450483 | D29: ='User Growth'!AL28 -> 763599
A30: Total Paid | B30: ='User Growth'!N29 -> 33672 | C30: ='User Growth'!Z29 -> 127804 | D30: ='User Growth'!AL29 -> 265175
A31: Paid % | B31: ='User Growth'!N30 -> 0.19532909 | C31: ='User Growth'!Z30 -> 0.28370438 | D31: ='User Growth'!AL30 -> 0.34726997
A32: MRR | B32: =Revenue!N8 -> 350222.45 | C32: =Revenue!Z8 -> 1401028.2 | D32: =Revenue!AL8 -> 3031361.3
A33: ARR | B33: =Revenue!N9 -> 4202669.4 | C33: =Revenue!Z9 -> 16812339 | D33: =Revenue!AL9 -> 36376335
A34: Gross Margin | B34: =Costs!N22 -> 0.74829969 | C34: =Costs!Z22 -> 0.78300947 | D34: =Costs!AL22 -> 0.80038222
A35: Op Margin | B35: =Costs!N24 -> 0.00098268343 | C35: =Costs!Z24 -> 0.28675142 | D35: =Costs!AL24 -> 0.43346842
A36: NRR (monthly) | B36: =Revenue!N19 -> 0.96914539 | C36: =Revenue!Z19 -> 0.9711221 | D36: =Revenue!AL19 -> 0.97160719
A38: BREAK-EVEN ANALYSIS
A39: Plus % of total MAU at break-even | B39: 0.16 | C39: Actual model ratio at M15 (~15.9%)
A40: Pro % of total MAU at break-even | B40: 0.06 | C40: Actual model ratio at M15 (~6.0%)
A41: Free % of total MAU (derived) | B41: =1-B39-B40 -> 0.78
A43: PER-USER ECONOMICS AT BREAK-EVEN MIX
A44: Revenue per MAU (monthly) | B44: =B39*Assumptions!$B$29+B40*Assumptions!$B$30 -> 2.304354 | C44: Plus% x ARPU_plus + Pro% x ARPU_pro
A45: COGS per MAU (monthly) | B45: =B41*Assumptions!$B$34+(B39+B40)*Assumptions!$B$33 -> 0.557 | C45: Free% x COGS_free + Paid% x COGS_paid
A46: Marketing cost per MAU (% of rev) | B46: =B44*Assumptions!$B$62 -> 0.5760885
A47: Net contribution per MAU | B47: =B44-B45-B46 -> 1.1712655 | C47: Revenue - COGS - Marketing per user per month
...

Sheet Cash Flow
A1: POSEIDON.AI — Cash Flow & Funding
A2: Burn Rate, Runway, Seed + Series A
A4: Metric | B4: Units | C4: M1 | D4: M2 | E4: M3 | F4: M4 | G4: M5 | H4: M6 | I4: M7 | J4: M8 | K4: M9 | L4: M10 | M4: M11 | N4: M12 | O4: M13 | P4: M14 | Q4: M15 | R4: M16 | S4: M17 | T4: M18 | U4: M19 | V4: M20 | W4: M21 | X4: M22 | Y4: M23 | Z4: M24 | AA4: M25 | AB4: M26 | AC4: M27 | AD4: M28 | AE4: M29 | AF4: M30 | AG4: M31 | AH4: M32 | AI4: M33 | AJ4: M34 | AK4: M35 | AL4: M36
A5: OPERATING CASH FLOW
A6: Revenue | B6: $ | C6: =Revenue!C16 -> 4184.7117 | D6: =Revenue!D16 -> 12650.874 | E6: =Revenue!E16 -> 25454.286 | F6: =Revenue!F16 -> 42702.819 | G6: =Revenue!G16 -> 64470.864 | H6: =Revenue!H16 -> 90851.402 | I6: =Revenue!I16 -> 121922.55 | J6: =Revenue!J16 -> 157781 | ... AL6: =Revenue!AL16 -> 3031361.3
A7: Total Costs | B7: $ | C7: =Costs!C20 -> 139032.37 | D7: =Costs!D20 -> 142507.97 | E7: =Costs!E20 -> 148294.15 | F7: =Costs!F20 -> 157979.91 | G7: =Costs!G20 -> 169750.41 | H7: =Costs!H20 -> 183633.47 | I7: =Costs!I20 -> 237148.64 | J7: =Costs!J20 -> 255326.4 | ... AL7: =Costs!AL20 -> 1717361.9
A8: Net Burn / (Profit) | B8: $ | C8: =C6-C7 -> -134847.66 | D8: =D6-D7 -> -129857.1 | E8: =E6-E7 -> -122839.87 | F8: =F6-F7 -> -115277.1 | G8: =G6-G7 -> -105279.54 | H8: =H6-H7 -> -92782.068 | I8: =I6-I7 -> -115226.08 | J8: =J6-J7 -> -97545.399 | ... AL8: =AL6-AL7 -> 1313999.4
A9: FUNDING EVENTS
A10: Seed Round | B10: $ | C10: =Assumptions!B52 -> 5000000 | D10: =0 -> 0 | E10: =0 -> 0 | F10: =0 -> 0 | G10: =0 -> 0 | H10: =0 -> 0 | I10: =0 -> 0 | J10: =0 -> 0 | K10: =0 -> 0 | ... AL10: =0 -> 0
A11: Series A | B11: $ | C11: =0 -> 0 | D11: =IF(AND(Revenue!D8>=Assumptions!$B$56, Revenue!C8<Assumptions!$B$56), Assumptions!$B$54, 0) -> 0 | E11: =IF(AND(Revenue!E8>=Assumptions!$B$56, Revenue!D8<Assumptions!$B$56), Assumptions!$B$54, 0) -> 0 | F11: =IF(AND(Revenue!F8>=Assumptions!$B$56, Revenue!E8<Assumptions!$B$56), Assumptions!$B$54, 0) -> 0 | G11: =IF(AND(Revenue!G8>=Assumptions!$B$56, Revenue!F8<Assumptions!$B$56), Assumptions!$B$54, 0) -> 0 | H11: =IF(AND(Revenue!H8>=Assumptions!$B$56, Revenue!G8<Assumptions!$B$56), Assumptions!$B$54, 0) -> 0 | I11: =IF(AND(Revenue!I8>=Assumptions!$B$56, Revenue!H8<Assumptions!$B$56), Assumptions!$B$54, 0) -> 0 | J11: =IF(AND(Revenue!J8>=Assumptions!$B$56, Revenue!I8<Assumptions!$B$56), Assumptions!$B$54, 0) -> 0 | K11: =IF(AND(Revenue!K8>=Assumptions!$B$56, Revenue!J8<Assumptions!$B$56), Assumptions!$B$54, 0) -> 0 | ... AL11: =IF(AND(Revenue!AL8>=Assumptions!$B$56, Revenue!AK8<Assumptions!$B$56), Assumptions!$B$54, 0) -> 0
A12: Total Funding In | B12: $ | C12: =C10+C11 -> 5000000 | D12: =D10+D11 -> 0 | E12: =E10+E11 -> 0 | F12: =F10+F11 -> 0 | G12: =G10+G11 -> 0 | H12: =H10+H11 -> 0 | I12: =I10+I11 -> 0 | J12: =J10+J11 -> 0 | ... AL12: =AL10+AL11 -> 0
A13: CASH POSITION
A14: Cash — Beginning of Month | B14: $ | C14: =0 -> 0 | D14: =C18 -> 4865152.3 | E14: =D18 -> 4735295.2 | F14: =E18 -> 4612455.4 | G14: =F18 -> 4497178.3 | H14: =G18 -> 4391898.7 | I14: =H18 -> 4299116.7 | J14: =I18 -> 4183890.6 | K14: =J18 -> 4086345.2 | ... AL14: =AK18 -> 35385799
A15: Cash In (revenue + funding) | B15: $ | C15: =C6+C12 -> 5004184.7 | D15: =D6+D12 -> 12650.874 | E15: =E6+E12 -> 25454.286 | F15: =F6+F12 -> 42702.819 | G15: =G6+G12 -> 64470.864 | H15: =H6+H12 -> 90851.402 | I15: =I6+I12 -> 121922.55 | J15: =J6+J12 -> 157781 | ... AL15: =AL6+AL12 -> 3031361.3
A16: Cash Out (costs) | B16: $ | C16: =C7 -> 139032.37 | D16: =D7 -> 142507.97 | E16: =E7 -> 148294.15 | F16: =F7 -> 157979.91 | G16: =G7 -> 169750.41 | H16: =H7 -> 183633.47 | I16: =I7 -> 237148.64 | J16: =J7 -> 255326.4 | ... AL16: =AL7 -> 1717361.9
A17: Net Cash Flow | B17: $ | C17: =C15-C16 -> 4865152.3 | D17: =D15-D16 -> -129857.1 | E17: =E15-E16 -> -122839.87 | F17: =F15-F16 -> -115277.1 | G17: =G15-G16 -> -105279.54 | H17: =H15-H16 -> -92782.068 | I17: =I15-I16 -> -115226.08 | J17: =J15-J16 -> -97545.399 | ... AL17: =AL15-AL16 -> 1313999.4
A18: Cash — End of Month | B18: $ | C18: =C14+C17 -> 4865152.3 | D18: =D14+D17 -> 4735295.2 | E18: =E14+E17 -> 4612455.4 | F18: =F14+F17 -> 4497178.3 | G18: =G14+G17 -> 4391898.7 | H18: =H14+H17 -> 4299116.7 | I18: =I14+I17 -> 4183890.6 | J18: =J14+J17 -> 4086345.2 | ... AL18: =AL14+AL17 -> 36699798
A19: RUNWAY & BURN
A20: Runway (months at current burn) | B20: # | C20: =IF(C8>=0, 999, -1*C18/C8) -> 36.078879 | D20: =IF(D8>=0, 999, -1*D18/D8) -> 36.465433 | E20: =IF(E8>=0, 999, -1*E18/E8) -> 37.548522 | F20: =IF(F8>=0, 999, -1*F18/F8) -> 39.011898 | G20: =IF(G8>=0, 999, -1*G18/G8) -> 41.716545 | H20: =IF(H8>=0, 999, -1*H18/H8) -> 46.335642 | I20: =IF(I8>=0, 999, -1*I18/I8) -> 36.310273 | J20: =IF(J8>=0, 999, -1*J18/J8) -> 41.891726 | ... AL20: =IF(AL8>=0, 999, -1*AL18/AL8) -> 999
A21: Cumulative Net Burn | B21: $ | C21: =C8 -> -134847.66 | D21: =C21+D8 -> -264704.75 | E21: =D21+E8 -> -387544.62 | F21: =E21+F8 -> -502821.72 | G21: =F21+G8 -> -608101.26 | H21: =G21+H8 -> -700883.33 | I21: =H21+I8 -> -816109.41 | J21: =I21+J8 -> -913654.81 | K21: =J21+K8 -> -990846.71 | ... AL21: =AK21+AL8 -> 11699798

Sheet Dashboard
A1: POSEIDON.AI — Financial Dashboard
A3: Month | B3: M1 | C3: M2 | D3: M3 | E3: M4 | F3: M5 | G3: M6 | H3: M7 | I3: M8 | J3: M9 | K3: M10 | L3: M11 | M3: M12 | N3: M13 | O3: M14 | P3: M15 | Q3: M16 | R3: M17 | S3: M18 | T3: M19 | U3: M20 | V3: M21 | W3: M22 | X3: M23 | Y3: M24 | Z3: M25 | AA3: M26 | AB3: M27 | AC3: M28 | AD3: M29 | AE3: M30 | AF3: M31 | AG3: M32 | AH3: M33 | AI3: M34 | AJ3: M35 | AK3: M36
A4: Total MAU | B4: ='User Growth'!C28 -> 9639 | C4: ='User Growth'!D28 -> 20109 | D4: ='User Growth'!E28 -> 31431 | E4: ='User Growth'!F28 -> 43617 | F4: ='User Growth'!G28 -> 56678 | G4: ='User Growth'!H28 -> 70619 | H4: ='User Growth'!I28 -> 85440 | I4: ='User Growth'!J28 -> 101135 | ... AK4: ='User Growth'!AL28 -> 763599
A5: Paid Users | B5: ='User Growth'!C29 -> 431 | C5: ='User Growth'!D29 -> 1291 | D5: ='User Growth'!E29 -> 2580 | E5: ='User Growth'!F29 -> 4299 | F5: ='User Growth'!G29 -> 6449 | G5: ='User Growth'!H29 -> 9032 | H5: ='User Growth'!I29 -> 12048 | I5: ='User Growth'!J29 -> 15501 | ... AK5: ='User Growth'!AL29 -> 265175
A6: MRR ($) | B6: =Revenue!C8 -> 4184.7117 | C6: =Revenue!D8 -> 12650.874 | D6: =Revenue!E8 -> 25454.286 | E6: =Revenue!F8 -> 42702.819 | F6: =Revenue!G8 -> 64470.864 | G6: =Revenue!H8 -> 90851.402 | H6: =Revenue!I8 -> 121922.55 | I6: =Revenue!J8 -> 157781 | ... AK6: =Revenue!AL8 -> 3031361.3
A7: ARR ($) | B7: =Revenue!C9 -> 50216.54 | C7: =Revenue!D9 -> 151810.48 | D7: =Revenue!E9 -> 305451.43 | E7: =Revenue!F9 -> 512433.83 | F7: =Revenue!G9 -> 773650.37 | G7: =Revenue!H9 -> 1090216.8 | H7: =Revenue!I9 -> 1463070.6 | I7: =Revenue!J9 -> 1893372 | ... AK7: =Revenue!AL9 -> 36376335
A8: Cash ($) | B8: ='Cash Flow'!C18 -> 4865152.3 | C8: ='Cash Flow'!D18 -> 4735295.2 | D8: ='Cash Flow'!E18 -> 4612455.4 | E8: ='Cash Flow'!F18 -> 4497178.3 | F8: ='Cash Flow'!G18 -> 4391898.7 | G8: ='Cash Flow'!H18 -> 4299116.7 | H8: ='Cash Flow'!I18 -> 4183890.6 | I8: ='Cash Flow'!J18 -> 4086345.2 | ... AK8: ='Cash Flow'!AL18 -> 36699798
A9: Op Profit ($) | B9: =Costs!C23 -> -134847.66 | C9: =Costs!D23 -> -129857.1 | D9: =Costs!E23 -> -122839.87 | E9: =Costs!F23 -> -115277.1 | F9: =Costs!G23 -> -105279.54 | G9: =Costs!H23 -> -92782.068 | H9: =Costs!I23 -> -115226.08 | I9: =Costs!J23 -> -97545.399 | ... AK9: =Costs!AL23 -> 1313999.4
A10: Gross Margin | B10: =Costs!C22 -> 0.46395351 | C10: =Costs!D22 -> 0.57278049 | D10: =Costs!E22 -> 0.62726709 | E10: =Costs!F22 -> 0.66054466 | F10: =Costs!G22 -> 0.68307622 | G10: =Costs!H22 -> 0.69948675 | H10: =Costs!I22 -> 0.71207296 | I10: =Costs!J22 -> 0.72210152 | ... AK10: =Costs!AL22 -> 0.80038222
A11: NRR (%) | B11: =Revenue!C19 -> 0 | C11: =Revenue!D19 -> 0.9254682 | D11: =Revenue!E19 -> 0.94951515 | E11: =Revenue!F19 -> 0.95740221 | F11: =Revenue!G19 -> 0.9614768 | G11: =Revenue!H19 -> 0.96382713 | H11: =Revenue!I19 -> 0.96554211 | I11: =Revenue!J19 -> 0.96670819 | ... AK11: =Revenue!AL19 -> 0.97160719

Sheet Slide Metrics
A1: POSEIDON.AI — Slide Metrics Calculation Basis
A2: All slide figures should be traceable to formulas in this sheet.
A4: SLIDE 9: STRATEGY SUMMARY — Business Model Card
A5: Metric | B5: Model Value | C5: Slide Value | D5: Match? | E5: Formula / Source
A6: Gross Margin (at M12) | B6: =Costs!N22 -> 0.74829969 | C6: 87% | D6: MISMATCH | E6: Model: ~74.5% at M12. 87% not reached at any month. Slide needs correction.
A7: Gross Margin (at M18) | B7: =Costs!T22 -> 0.76969308 | D7: REF | E7: 76.5% at M18. Max in model is 79.3% at M36.
A8: Gross Margin (at M36) | B8: =Costs!AL22 -> 0.80038222 | D8: REF | E8: 79.3% at M36. Theoretical max if COGS goes to $0 = 100%.
A9: Op. Break-even Month | B9: ='Unit Economics'!B67 -> 12 | C9: Month 12 | D9: MISMATCH | E9: Model: M10 is first month with positive OpProfit ($27,526). M9 = -$13,272.
A10: Value / Cost — Plus (Customer ROI) | B10: =Assumptions!B74 -> 4.6933667
A11: Value / Cost — Pro (Customer ROI) | B11: =Assumptions!B75 -> 3.3350008
A12: Value / Cost — Blended (slide uses this) | B12: =(Assumptions!B74*'Unit Economics'!B39+Assumptions!B75*'Unit Economics'!B40)/('Unit Economics'!B39+'Unit Economics'!B40) -> 4.3229033 | C12: 6x | D12: ~OK | E12: Blended = (5.2x * 16% + 7.5x * 6%) / (16% + 6%) = ~5.8x. Slide rounds to 6x.
A14: SLIDE 11: BUSINESS MODEL DETAIL
A15: Metric | B15: Model Value | C15: Slide Value | D15: Match? | E15: Formula / Source
A16: LTV / CAC — Plus | B16: ='Unit Economics'!B14 -> 10.010507 | C16: 17x | D16: MISMATCH | E16: Model: 10.0x = LTV $108.61 / CAC $10.85. Slide says 17x.
A17: LTV / CAC — Pro | B17: ='Unit Economics'!B15 -> 50.969892 | C17: 77x | D17: MISMATCH | E17: Model: 51.0x = LTV $553.02 / CAC $10.85. Slide says 77x.
A18: LTV — Plus | B18: ='Unit Economics'!B12 -> 108.614
A19: LTV — Pro | B19: ='Unit Economics'!B13 -> 553.02333
A20: Blended CAC | B20: ='Unit Economics'!B5 -> 10.85
A21: Contribution Margin — Plus | B21: ='Unit Economics'!B21 -> 0.73084635 | C21: 73% | D21: OK
A22: Contribution Margin — Pro | B22: ='Unit Economics'!B26 -> 0.89241933 | C22: 89% | D22: OK
A23: Gross Margin (slide label) | B23: =Costs!N22 -> 0.74829969 | C23: 86% | D23: MISMATCH | E23: Model Gross Margin at M12 = 74.5%. 86% is not a model output. Possibly confused with Pro contribution margin (89%).
A24: Operating Breakeven Month | B24: ='Unit Economics'!B67 -> 12 | D24: MISMATCH | E24: Model: M10. M9 OpProfit=-$13,272, M10=+$27,526. Month 6 is incorrect.
A26: J-CURVE CHART MILESTONES
A27: Metric | B27: Model Value | C27: Slide Value | D27: Match? | E27: Formula / Source
A28: Monthly Breakeven (OpProfit >= 0) | B28: ='Unit Economics'!B67 -> 12 | E28: Month where Costs!Row23 first >= 0. M10: OpProfit = $27,526.
A29: MRR at Breakeven | B29: ='Unit Economics'!B71 -> 350222.45 | E29: Revenue!Row8 at breakeven month = $420,277
A30: ARR at Breakeven | B30: ='Unit Economics'!B72 -> 4202669.4
A31: Cumulative Payback (CumBurn >= 0) | B31: =SUMPRODUCT(--('Cash Flow'!C21:AL21<0))+1 -> 21 | E31: Month where Cash Flow!Row21 (Cumulative Net Burn) first >= 0. M15: +$202,352.
A32: Series A Trigger (MRR >= $300K) | B32: =SUMPRODUCT(--(Revenue!C8:AL8<Assumptions!$B$56))+1 -> 12 | E32: Month where MRR first >= $300K. M9: MRR = $338,699.
A33: M18 ARR | B33: =Revenue!T9 -> 9467056.5
A34: M18 Monthly Op Profit | B34: =Costs!T23 -> 231943.82 | E34: Revenue - Total Costs = $576,600/mo
A36: MARKET OPPORTUNITY (requires external sources)
A37: Metric | B37: Model Value | C37: Slide Value | D37: Match? | E37: Formula / Source
A38: TAM — US Personal Finance Software | B38: 3500000 | C38: $7B | D38: VERIFY | E38: Source needed. US personal finance software market. Verify with Statista/IBISWorld.
A39: SAM — AI-Native Financial Coordination | B39: 1500000 | C39: $1.5B | D39: VERIFY | E39: Source needed. Subset of TAM for AI-powered coordination tools. Justify % of TAM.
A40: 3-Year Revenue Capture (from model) | B40: =Revenue!AL17 -> 38930138 | C40: $25M | D40: MISMATCH | E40: Model cumulative revenue M1-M36 = $83.8M. $25M appears to be ~Year 1+partial Year 2.
A41: Year 1 Revenue (M1-M12) | B41: =SUM(Revenue!C16:N16) -> 1607481.9
A42: Year 2 Revenue (M13-M24) | B42: =SUM(Revenue!O16:Z16) -> 10345371
A43: Year 3 Revenue (M25-M36) | B43: =SUM(Revenue!AA16:AL16) -> 26977285
A45: HEADCOUNT & AI LEVERAGE (Subtitle Basis)
...
